<!-- BEGIN KEY -->
public class javax.naming.NameAlreadyBoundException extends javax.naming.NamingException
<!-- END KEY -->
<!-- BEGIN DATA -->
一些方法抛出此异常来指示因为名称已经绑定到另一个对象而无法添加某一绑定。
 <p>
应用于 NamingException 的同步和序列化问题在这里可以直接应用。

@author Rosanna Lee
@author Scott Seligman
@version 1.8 05/11/17

@see Context#bind
@see Context#rebind
@see Context#createSubcontext
@see javax.naming.directory.DirContext#bind
@see javax.naming.directory.DirContext#rebind
@see javax.naming.directory.DirContext#createSubcontext
@since 1.3

<!-- END DATA -->
<!-- BEGIN KEY -->
public javax.naming.NameAlreadyBoundException(String explanation)
<!-- END KEY -->
<!-- BEGIN DATA -->
使用所提供的解释构造一个新的 NameAlreadyBoundException 实例。其他所有字段都默认为 null。

@param	explanation	有关此异常的可能为 null 的附加详细信息。
@see java.lang.Throwable#getMessage

<!-- END DATA -->
<!-- BEGIN KEY -->
public javax.naming.NameAlreadyBoundException()
<!-- END KEY -->
<!-- BEGIN DATA -->
构造一个新的 NameAlreadyBoundException 实例。所有字段都被设置为 null。

<!-- END DATA -->
